Traceback (most recent call last):
  File "/Users/dialidsantiago/Git/Plotly-Dash-Cookbook/.venv/lib/python3.11/site-packages/jupyter_cache/executors/utils.py", line 58, in single_nb_execution
    executenb(
  File "/Users/dialidsantiago/Git/Plotly-Dash-Cookbook/.venv/lib/python3.11/site-packages/nbclient/client.py", line 1314, in execute
    return NotebookClient(nb=nb, resources=resources, km=km, **kwargs).execute()
           ^^^^^^^^^^^^^^^^^^^^^^^^^^^^^^^^^^^^^^^^^^^^^^^^^^^^^^^^^^^^^^^^^^^^^
  File "/Users/dialidsantiago/Git/Plotly-Dash-Cookbook/.venv/lib/python3.11/site-packages/jupyter_core/utils/__init__.py", line 165, in wrapped
    return loop.run_until_complete(inner)
           ^^^^^^^^^^^^^^^^^^^^^^^^^^^^^^
  File "/Library/Frameworks/Python.framework/Versions/3.11/lib/python3.11/asyncio/base_events.py", line 653, in run_until_complete
    return future.result()
           ^^^^^^^^^^^^^^^
  File "/Users/dialidsantiago/Git/Plotly-Dash-Cookbook/.venv/lib/python3.11/site-packages/nbclient/client.py", line 709, in async_execute
    await self.async_execute_cell(
  File "/Users/dialidsantiago/Git/Plotly-Dash-Cookbook/.venv/lib/python3.11/site-packages/nbclient/client.py", line 1062, in async_execute_cell
    await self._check_raise_for_error(cell, cell_index, exec_reply)
  File "/Users/dialidsantiago/Git/Plotly-Dash-Cookbook/.venv/lib/python3.11/site-packages/nbclient/client.py", line 918, in _check_raise_for_error
    raise CellExecutionError.from_cell_and_msg(cell, exec_reply_content)
nbclient.exceptions.CellExecutionError: An error occurred while executing the following cell:
------------------
fig = px.scatter(df, x="Country ISO3", y="Value", 
                 color="Sex",
                 symbol="Sex",
                 color_discrete_map = {'Female':'purple', 'Male':'Green'},
                 title="Women as a share of all 16-24 year-olds who can program",
                 width=900, height=500
                )
fig.update_layout(xaxis={'tickangle'=-90})
fig.show()
------------------


[0;36m  Cell [0;32mIn[13], line 8[0;36m[0m
[0;31m    fig.update_layout(xaxis={'tickangle'=-90})[0m
[0m                             ^[0m
[0;31mSyntaxError[0m[0;31m:[0m cannot assign to literal here. Maybe you meant '==' instead of '='?


